Workbook

Sheet Config
A1: SMB Commerce OS — Build Calendar Configuration
A2: Set the two blue cells below. Every date in this workbook recalculates from them.
A4: Setting | B4: Value | C4: Notes
A5: Build start date | B5: 46279 | C5: First build day. Must be a weekday.
A6: Build days per week | B6: 3 | C6: 3 = part-time (realistic alongside other commitments). 5 = full-time.
A8: Derived
A9: Total build days | B9: =COUNT('Daily Plan'!A5:A180)
A10: MVP gate date (D136, end of Phase 7) | B10: =INDEX('Daily Plan'!$B:$B,136+4)
A11: Final day date (D176) | B11: =INDEX('Daily Plan'!$B:$B,176+4)
A12: Elapsed weeks to MVP gate | B12: =ROUND((B10-B5)/7,1)
A13: Elapsed weeks total | B13: =ROUND((B11-B5)/7,1)
A15: Legend
A16: Blue text on yellow fill | B16: Input cell — you edit these
A17: Black text | B17: Formula — do not overwrite
A18: Green row fill (Daily Plan) | B18: Phase gate day
A19: Orange row fill (Daily Plan) | B19: MVP gate (D136)
A20: Status values | B20: Not started / In progress / Done / Carried / Blocked
A23: Dates are computed as WORKDAY(start, (day-1) x 5 / days_per_week), so the schedule stretches
A24: across calendar weeks according to your chosen cadence. Holidays are not modelled — carry cards as needed.

Sheet Phase Summary
A1: Phase Summary
A2: Dates recalculate from the Config sheet. A gate passes when its acceptance test passes in CI, not when the date arrives.
A4: Phase | B4: Name | C4: First day | D4: Last day | E4: Days | F4: Start date | G4: End date | H4: Gate | I4: Gate acceptance criterion
A5: 0 | B5: Foundations & Security Baseline | C5: D001 | D5: D012 | E5: 12 | F5: =INDEX('Daily Plan'!$B:$B,1+4) | G5: =INDEX('Daily Plan'!$B:$B,12+4) | H5: G0 | I5: Repo, CI, and security gates green on an empty app
A6: 1 | B6: Domain Model & Database | C6: D013 | D6: D030 | E6: 18 | F6: =INDEX('Daily Plan'!$B:$B,13+4) | G6: =INDEX('Daily Plan'!$B:$B,30+4) | H6: G1 | I6: Schema migrates on both dialects; tenant isolation proven by test
A7: 2 | B7: Catalog & Product Inventory | C7: D031 | D7: D044 | E7: 14 | F7: =INDEX('Daily Plan'!$B:$B,31+4) | G7: =INDEX('Daily Plan'!$B:$B,44+4) | H7: G2 | I7: A product can be listed, stocked, and sold
A8: 3 | B8: Availability Engine & Services | C8: D045 | D8: D062 | E8: 18 | F8: =INDEX('Daily Plan'!$B:$B,45+4) | G8: =INDEX('Daily Plan'!$B:$B,62+4) | H8: G3 | I8: No double-booking under real concurrent load, both dialects
A9: 4 | B9: Rentals, Deposits & Returns | C9: D063 | D9: D086 | E9: 24 | F9: =INDEX('Daily Plan'!$B:$B,63+4) | G9: =INDEX('Daily Plan'!$B:$B,86+4) | H9: G4 | I9: Full rental lifecycle including deposit settlement
A10: 5 | B10: Payments — Stripe Connect | C10: D087 | D10: D100 | E10: 14 | F10: =INDEX('Daily Plan'!$B:$B,87+4) | G10: =INDEX('Daily Plan'!$B:$B,100+4) | H10: G5 | I10: Money moves correctly in all three modes
A11: 6 | B11: Merchant Dashboard (Web) | C11: D101 | D11: D120 | E11: 20 | F11: =INDEX('Daily Plan'!$B:$B,101+4) | G11: =INDEX('Daily Plan'!$B:$B,120+4) | H11: G6 | I11: A merchant can operate unaided
A12: 7 | B12: Customer Storefront (Web) | C12: D121 | D12: D136 | E12: 16 | F12: =INDEX('Daily Plan'!$B:$B,121+4) | G12: =INDEX('Daily Plan'!$B:$B,136+4) | H12: G7 | I12: MVP GATE — pilot-capable, web only
A13: 8 | B13: Mobile Application | C13: D137 | D13: D152 | E13: 16 | F13: =INDEX('Daily Plan'!$B:$B,137+4) | G13: =INDEX('Daily Plan'!$B:$B,152+4) | H13: G8 | I13: Parity for customer flows on iOS and Android
A14: 9 | B14: Security Hardening & Compliance Pack | C14: D153 | D14: D166 | E14: 14 | F14: =INDEX('Daily Plan'!$B:$B,153+4) | G14: =INDEX('Daily Plan'!$B:$B,166+4) | H14: G9 | I14: Pen test clean; compliance evidence assembled
A15: 10 | B15: Pilot Readiness & Launch | C15: D167 | D15: D176 | E15: 10 | F15: =INDEX('Daily Plan'!$B:$B,167+4) | G15: =INDEX('Daily Plan'!$B:$B,176+4) | H15: G10 | I15: First merchant live
B16: TOTAL | E16: =SUM(E5:E15) | F16: =Config!B5 | G16: =G15

Sheet Daily Plan
A1: Daily Plan — one card per build day
A2: One card, one day, one merge. If a card cannot be finished and verified in a day it was scoped wrong — split it before starting. Mark Carried rather than extending a card silently.
A4: Day | B4: Date | C4: Ph | D4: Phase | E4: Epic | F4: Task | G4: Deliverable | H4: Acceptance criteria | I4: Security check | J4: Status | K4: Hrs | L4: Notes | M4: Card (prompt) | N4: Log | O4: Est. Duration (AI session)
A5: 1 | B5: =WORKDAY(Config!$B$5,ROUND((A5-1)*5/Config!$B$6,0)) | C5: 0 | D5: Foundations & Security Baseline | E5: Toolchain | F5: Initialize monorepo | G5: pnpm workspaces + Turborepo; apps/ and packages/ per ADR-001 | H5: `pnpm install` succeeds; workspace graph resolves | I5: No secrets in initial commit; .gitignore covers .env | J5: Not started | M5: D001 | N5: D001 | O5: 1.0h
A6: 2 | B6: =WORKDAY(Config!$B$5,ROUND((A6-1)*5/Config!$B$6,0)) | C6: 0 | D6: Foundations & Security Baseline | E6: Toolchain | F6: TypeScript strict configuration | G6: Shared tsconfig package, strict mode, no implicit any | H6: `tsc --noEmit` passes across all packages | I6: Strict null checks reduce a class of runtime defects | J6: Not started | M6: D002 | N6: D002 | O6: 1.0h
A7: 3 | B7: =WORKDAY(Config!$B$5,ROUND((A7-1)*5/Config!$B$6,0)) | C7: 0 | D7: Foundations & Security Baseline | E7: Toolchain | F7: Lint and format rules | G7: ESLint + Prettier; custom rule banning raw SQL outside packages/db | H7: Lint fails on a deliberate raw-SQL violation in apps/api | I7: Rule enforces the dialect + tenant-scoping boundary | J7: Not started | M7: D003 | N7: D003 | O7: 1.0h
A8: 4 | B8: =WORKDAY(Config!$B$5,ROUND((A8-1)*5/Config!$B$6,0)) | C8: 0 | D8: Foundations & Security Baseline | E8: Toolchain | F8: Test harness | G8: Vitest configured; coverage thresholds set per 10_secure_sdlc | H8: `pnpm test` runs; coverage gate fails below threshold | I8: Domain package threshold set to 95% | J8: Not started | M8: D004 | N8: D004 | O8: 1.0h
A9: 5 | B9: =WORKDAY(Config!$B$5,ROUND((A9-1)*5/Config!$B$6,0)) | C9: 0 | D9: Foundations & Security Baseline | E9: CI/CD | F9: CI pipeline skeleton | G9: Workflow: install, lint, typecheck, test on every PR | H9: Pipeline green on an empty app | I9: Frozen lockfile prevents dependency substitution | J9: Not started | M9: D005 | N9: D005 | O9: 1.0h
A10: 6 | B10: =WORKDAY(Config!$B$5,ROUND((A10-1)*5/Config!$B$6,0)) | C10: 0 | D10: Foundations & Security Baseline | E10: CI/CD | F10: Secret scanning | G10: gitleaks in pre-commit hook and CI | H10: Planted test secret fails the build | I10: Any finding fails build; rotation procedure documented | J10: Not started | M10: D006 | N10: D006 | O10: 1.0h
A11: 7 | B11: =WORKDAY(Config!$B$5,ROUND((A11-1)*5/Config!$B$6,0)) | C11: 0 | D11: Foundations & Security Baseline | E11: CI/CD | F11: Dependency scanning and SBOM | G11: Scanner in CI; SBOM generated and retained as artifact | H11: Build fails on a high/critical with a fix available | I11: SBOM is the dependency-inventory evidence for control ID | J11: Not started | M11: D007 | N11: D007 | O11: 1.0h
A12: 8 | B12: =WORKDAY(Config!$B$5,ROUND((A12-1)*5/Config!$B$6,0)) | C12: 0 | D12: Foundations & Security Baseline | E12: CI/CD | F12: SAST | G12: CodeQL or Semgrep in CI | H12: Build fails on high/critical finding | I12: Static analysis before any application code exists | J12: Not started | M12: D008 | N12: D008 | O12: 1.0h
A13: 9 | B13: =WORKDAY(Config!$B$5,ROUND((A13-1)*5/Config!$B$6,0)) | C13: 0 | D13: Foundations & Security Baseline | E13: CI/CD | F13: Branch protection and PR template | G13: Protection rules; PR template with self-review checklist; conventional commits | H13: Direct push to main rejected | I13: Self-review checklist is the CC8 change-management evidence | J13: Not started | M13: D009 | N13: D009 | O13: 1.0h
A14: 10 | B14: =WORKDAY(Config!$B$5,ROUND((A14-1)*5/Config!$B$6,0)) | C14: 0 | D14: Foundations & Security Baseline | E14: Security foundation | F14: Native AuthProvider implementation | G14: AuthProvider interface + NativeAuthProvider (Argon2id, sessions, rate limiting) per ADR-002; Auth0 deferred, interface keeps swap-in possible later | H14: Register/login/authenticated-route/logout/reset-initiation all pass against NativeAuthProvider; test proves no module imports NativeAuthProvider directly except via the interface | I14: Argon2id hashing, no plaintext/bcrypt; login+reset rate-limited from this card; sessions revocable server-side; see docs/adr/ADR-002-authentication-provider.md | J14: Not started | L14: Revised per ADR-002 (2026-09-07): was 'Identity provider spike / OIDC PKCE'. Founder decision: native auth now, Auth0-ready interface, Auth0 wired in later. | M14: D010 | N14: D010 | O14: 4.0h
A15: 11 | B15: =WORKDAY(Config!$B$5,ROUND((A15-1)*5/Config!$B$6,0)) | C15: 0 | D15: Foundations & Security Baseline | E15: Security foundation | F15: Security policy set | G15: /docs/compliance/policies drafted from GRC templates | H15: Six core policies committed and reviewed via PR | I15: Policies in version control give change history and effective dates | J15: Not started | M15: D011 | N15: D011 | O15: 1.0h
A16: 12 | B16: =WORKDAY(Config!$B$5,ROUND((A16-1)*5/Config!$B$6,0)) | C16: 0 | D16: Foundations & Security Baseline | E16: Security foundation | F16: Threat model, IR plan, subprocessors — GATE G0 | G16: Threat model reviewed; incident-response.md; subprocessors.md | H16: G0 record filed; all CI gates green on empty app | I16: Baseline threat model recorded before any feature exists | J16: Not started | M16: D012 | N16: D012 | O16: 2.5h
A17: 13 | B17: =WORKDAY(Config!$B$5,ROUND((A17-1)*5/Config!$B$6,0)) | C17: 1 | D17: Domain Model & Database | E17: Database foundation | F17: SQLite connection layer | G17: Drizzle + SQLite; WAL, foreign_keys ON, busy_timeout set | H17: PRAGMA values asserted by a startup test | I17: foreign_keys ON — off by default in SQLite, a silent divergence from PG | J17: Not started | M17: D013 | N17: D013 | O17: 2.0h
A18: 14 | B18: =WORKDAY(Config!$B$5,ROUND((A18-1)*5/Config!$B$6,0)) | C18: 1 | D18: Domain Model & Database | E18: Database foundation | F18: PostgreSQL connection and CI matrix | G18: PG config; CI runs the suite against both dialects | H18: Both dialect jobs green | I18: Portability failure is caught the day it is written | J18: Not started | M18: D014 | N18: D014 | O18: 3.0h
A19: 15 | B19: =WORKDAY(Config!$B$5,ROUND((A19-1)*5/Config!$B$6,0)) | C19: 1 | D19: Domain Model & Database | E19: Database foundation | F19: Migration tooling | G19: drizzle-kit; forward-only policy; both-dialect migration check in CI | H19: A PG-incompatible migration fails CI | I19: Migration review is part of the security review triggers | J19: Not started | M19: D015 | N19: D015 | O19: 3.0h
A20: 16 | B20: =WORKDAY(Config!$B$5,ROUND((A20-1)*5/Config!$B$6,0)) | C20: 1 | D20: Domain Model & Database | E20: Database foundation | F20: Core utilities | G20: UUIDv7 generator; Money minor-unit value object; UTC time helpers | H20: Property tests: no float money; all timestamps UTC | I20: Money as integer minor units — floats are unacceptable for money | J20: Not started | M20: D016 | N20: D016 | O20: 2.0h
A21: 17 | B21: =WORKDAY(Config!$B$5,ROUND((A21-1)*5/Config!$B$6,0)) | C21: 1 | D21: Domain Model & Database | E21: Tenancy | F21: TenantContext and repository base | G21: TenantContext type; base class injecting merchant_id predicate | H21: Repository method without ctx is a compile error | I21: Control #1 — tenant isolation, layer 2 (type system) | J21: Not started | M21: D017 | N21: D017 | O21: 2.0h
A22: 18 | B22: =WORKDAY(Config!$B$5,ROUND((A22-1)*5/Config!$B$6,0)) | C22: 1 | D22: Domain Model & Database | E22: Tenancy | F22: Schema: tenancy tables | G22: merchants, users, merchant_users, locations | H22: Migrations apply on both dialects | I22: No password column on users — auth is delegated | J22: Not started | M22: D018 | N22: D018 | O22: 3.0h
A23: 19 | B23: =WORKDAY(Config!$B$5,ROUND((A23-1)*5/Config!$B$6,0)) | C23: 1 | D23: Domain Model & Database | E23: Tenancy | F23: Repository: merchants and locations | G23: Scoped repository methods | H23: CRUD works; scoping predicate present in every query | I23: Layer 3 — runtime scope injection | J23: Not started | M23: D019 | N23: D019 | O23: 2.0h
A24: 20 | B24: =WORKDAY(Config!$B$5,ROUND((A24-1)*5/Config!$B$6,0)) | C24: 1 | D24: Domain Model & Database | E24: Tenancy | F24: Repository: users and merchant_users | G24: Scoped repository + role assignment | H24: Role assignment restricted to OWNER | I24: Role changes are audit-logged and notified | J24: Not started | M24: D020 | N24: D020 | O24: 2.0h
A25: 21 | B25: =WORKDAY(Config!$B$5,ROUND((A25-1)*5/Config!$B$6,0)) | C25: 1 | D25: Domain Model & Database | E25: Tenancy | F25: Cross-tenant isolation test generator | G25: Suite generated from repository interfaces | H25: New repository method without a test fails the build | I25: THE critical control. Never waivable | J25: Not started | M25: D021 | N25: D021 | O25: 2.5h
A26: 22 | B26: =WORKDAY(Config!$B$5,ROUND((A26-1)*5/Config!$B$6,0)) | C26: 1 | D26: Domain Model & Database | E26: Schema build-out | F26: Schema: catalog | G26: listings (mode discriminator, immutable), listing_variants | H26: Mode CHECK constraints reject invalid mode-specific fields | I26: Mode immutability prevents capacity-strategy confusion | J26: Not started | M26: D022 | N26: D022 | O26: 2.0h
... A180: 176 | B180: =WORKDAY(Config!$B$5,ROUND((A180-1)*5/Config!$B$6,0)) | C180: 10 | D180: Pilot Readiness & Launch | E180: Production | F180: Post-launch review — GATE G10 | G180: Review of the first live week | H180: G10 record filed; issues triaged into a backlog | I180: Confirm retention and audit jobs running in production | J180: Not started | M180: D176 | N180: D176 | O180: 3.0h

Sheet Weekly Review
A1: Weekly Review Log
A2: 60 minutes, same day each week. Record the uncomfortable items — carried cards, skipped tests, slipping dates. Restate the projected end date each week from the actual completion rate, not from the original plan.
A4: Wk | B4: Week of | C4: Phase | D4: Planned | E4: Done | F4: Carried | G4: Blocked | H4: Rate % | I4: 4-wk rolling % | J4: Gate status | K4: New crit/high | L4: Remediated | M4: Tests skipped | N4: Domain cov % | O4: ADRs | P4: Scope change (days) | Q4: Risks changed | R4: Projected end | S4: Top blocker next week | T4: Notes
A5: 1 | B5: =Config!$B$5+(1-1)*7 | H5: =IFERROR(E5/D5,"") | I5: =IFERROR(SUM($E$5:E5)/SUM($D$5:D5),"")
A6: 2 | B6: =Config!$B$5+(2-1)*7 | H6: =IFERROR(E6/D6,"") | I6: =IFERROR(SUM($E$5:E6)/SUM($D$5:D6),"")
A7: 3 | B7: =Config!$B$5+(3-1)*7 | H7: =IFERROR(E7/D7,"") | I7: =IFERROR(SUM($E$5:E7)/SUM($D$5:D7),"")
A8: 4 | B8: =Config!$B$5+(4-1)*7 | H8: =IFERROR(E8/D8,"") | I8: =IFERROR(SUM(E5:E8)/SUM(D5:D8),"")
A9: 5 | B9: =Config!$B$5+(5-1)*7 | H9: =IFERROR(E9/D9,"") | I9: =IFERROR(SUM(E6:E9)/SUM(D6:D9),"")
A10: 6 | B10: =Config!$B$5+(6-1)*7 | H10: =IFERROR(E10/D10,"") | I10: =IFERROR(SUM(E7:E10)/SUM(D7:D10),"")
A11: 7 | B11: =Config!$B$5+(7-1)*7 | H11: =IFERROR(E11/D11,"") | I11: =IFERROR(SUM(E8:E11)/SUM(D8:D11),"")
A12: 8 | B12: =Config!$B$5+(8-1)*7 | H12: =IFERROR(E12/D12,"") | I12: =IFERROR(SUM(E9:E12)/SUM(D9:D12),"")
A13: 9 | B13: =Config!$B$5+(9-1)*7 | H13: =IFERROR(E13/D13,"") | I13: =IFERROR(SUM(E10:E13)/SUM(D10:D13),"")
A14: 10 | B14: =Config!$B$5+(10-1)*7 | H14: =IFERROR(E14/D14,"") | I14: =IFERROR(SUM(E11:E14)/SUM(D11:D14),"")
A15: 11 | B15: =Config!$B$5+(11-1)*7 | H15: =IFERROR(E15/D15,"") | I15: =IFERROR(SUM(E12:E15)/SUM(D12:D15),"")
A16: 12 | B16: =Config!$B$5+(12-1)*7 | H16: =IFERROR(E16/D16,"") | I16: =IFERROR(SUM(E13:E16)/SUM(D13:D16),"")
A17: 13 | B17: =Config!$B$5+(13-1)*7 | H17: =IFERROR(E17/D17,"") | I17: =IFERROR(SUM(E14:E17)/SUM(D14:D17),"")
A18: 14 | B18: =Config!$B$5+(14-1)*7 | H18: =IFERROR(E18/D18,"") | I18: =IFERROR(SUM(E15:E18)/SUM(D15:D18),"")
A19: 15 | B19: =Config!$B$5+(15-1)*7 | H19: =IFERROR(E19/D19,"") | I19: =IFERROR(SUM(E16:E19)/SUM(D16:D19),"")
A20: 16 | B20: =Config!$B$5+(16-1)*7 | H20: =IFERROR(E20/D20,"") | I20: =IFERROR(SUM(E17:E20)/SUM(D17:D20),"")
A21: 17 | B21: =Config!$B$5+(17-1)*7 | H21: =IFERROR(E21/D21,"") | I21: =IFERROR(SUM(E18:E21)/SUM(D18:D21),"")
A22: 18 | B22: =Config!$B$5+(18-1)*7 | H22: =IFERROR(E22/D22,"") | I22: =IFERROR(SUM(E19:E22)/SUM(D19:D22),"")
A23: 19 | B23: =Config!$B$5+(19-1)*7 | H23: =IFERROR(E23/D23,"") | I23: =IFERROR(SUM(E20:E23)/SUM(D20:D23),"")
A24: 20 | B24: =Config!$B$5+(20-1)*7 | H24: =IFERROR(E24/D24,"") | I24: =IFERROR(SUM(E21:E24)/SUM(D21:D24),"")
A25: 21 | B25: =Config!$B$5+(21-1)*7 | H25: =IFERROR(E25/D25,"") | I25: =IFERROR(SUM(E22:E25)/SUM(D22:D25),"")
A26: 22 | B26: =Config!$B$5+(22-1)*7 | H26: =IFERROR(E26/D26,"") | I26: =IFERROR(SUM(E23:E26)/SUM(D23:D26),"")
A27: 23 | B27: =Config!$B$5+(23-1)*7 | H27: =IFERROR(E27/D27,"") | I27: =IFERROR(SUM(E24:E27)/SUM(D24:D27),"")
A28: 24 | B28: =Config!$B$5+(24-1)*7 | H28: =IFERROR(E28/D28,"") | I28: =IFERROR(SUM(E25:E28)/SUM(D25:D28),"")
A29: 25 | B29: =Config!$B$5+(25-1)*7 | H29: =IFERROR(E29/D29,"") | I29: =IFERROR(SUM(E26:E29)/SUM(D26:D29),"")
A30: 26 | B30: =Config!$B$5+(26-1)*7 | H30: =IFERROR(E30/D30,"") | I30: =IFERROR(SUM(E27:E30)/SUM(D27:D30),"")
A31: 27 | B31: =Config!$B$5+(27-1)*7 | H31: =IFERROR(E31/D31,"") | I31: =IFERROR(SUM(E28:E31)/SUM(D28:D31),"")
A32: 28 | B32: =Config!$B$5+(28-1)*7 | H32: =IFERROR(E32/D32,"") | I32: =IFERROR(SUM(E29:E32)/SUM(D29:D32),"")
A33: 29 | B33: =Config!$B$5+(29-1)*7 | H33: =IFERROR(E33/D33,"") | I33: =IFERROR(SUM(E30:E33)/SUM(D30:D33),"")
A34: 30 | B34: =Config!$B$5+(30-1)*7 | H34: =IFERROR(E34/D34,"") | I34: =IFERROR(SUM(E31:E34)/SUM(D31:D34),"")
A35: 31 | B35: =Config!$B$5+(31-1)*7 | H35: =IFERROR(E35/D35,"") | I35: =IFERROR(SUM(E32:E35)/SUM(D32:D35),"")
A36: 32 | B36: =Config!$B$5+(32-1)*7 | H36: =IFERROR(E36/D36,"") | I36: =IFERROR(SUM(E33:E36)/SUM(D33:D36),"")
A37: 33 | B37: =Config!$B$5+(33-1)*7 | H37: =IFERROR(E37/D37,"") | I37: =IFERROR(SUM(E34:E37)/SUM(D34:D37),"")
A38: 34 | B38: =Config!$B$5+(34-1)*7 | H38: =IFERROR(E38/D38,"") | I38: =IFERROR(SUM(E35:E38)/SUM(D35:D38),"")
A39: 35 | B39: =Config!$B$5+(35-1)*7 | H39: =IFERROR(E39/D39,"") | I39: =IFERROR(SUM(E36:E39)/SUM(D36:D39),"")
A40: 36 | B40: =Config!$B$5+(36-1)*7 | H40: =IFERROR(E40/D40,"") | I40: =IFERROR(SUM(E37:E40)/SUM(D37:D40),"")
A41: 37 | B41: =Config!$B$5+(37-1)*7 | H41: =IFERROR(E41/D41,"") | I41: =IFERROR(SUM(E38:E41)/SUM(D38:D41),"")
...

Sheet Escalation Triggers
A1: Escalation Triggers
A2: Conditions that require a decision rather than another week of the same. From 13_weekly_review_protocol.md.
A4: Trigger | B4: Action
A5: Rolling completion below 60% for three weeks | B5: Re-plan. Reduce MVP scope or add capacity — do not simply extend the end date.
A6: The same card carried three times | B6: It is scoped wrong or blocked on something unrecognized. Stop and decompose it.
A7: A gate criterion failing two weeks running | B7: Stop the phase. Fix before proceeding.
A8: Critical scanner findings open beyond seven days | B8: Stop feature work until remediated.
A9: Any tenant-isolation or concurrency test skipped | B9: STOP IMMEDIATELY. These are never optional.
A10: Actual effort routinely exceeding planned by 50%+ | B10: The one-day card assumption is wrong for this phase; re-scope the remaining cards.
A11: Deposit reconciliation mismatch observed | B11: Treat as critical (T3). Halt payment-related work until root-caused.
A12: A production reservation overlap observed | B12: Treat as critical (T2). Halt and root-cause before any further release.
